teletouch >  Waking up the API... 
Traceback (most recent call last):
  File "teletouch/teletouch/receiver/receive.py", line 280, in <module>
    receive()
  File "teletouch/teletouch/receiver/receive.py", line 226, in receive
    r = requests.get('http://teletouch.herokuapp.com/api/wake')
  File "/usr/local/lib/python2.7/dist-packages/requests/api.py", line 70, in get
    return request('get', url, params=params, **kwargs)
  File "/usr/local/lib/python2.7/dist-packages/requests/api.py", line 56, in request
    return session.request(method=method, url=url, **kwargs)
  File "/usr/local/lib/python2.7/dist-packages/requests/sessions.py", line 488, in request
    resp = self.send(prep, **send_kwargs)
  File "/usr/local/lib/python2.7/dist-packages/requests/sessions.py", line 609, in send
    r = adapter.send(request, **kwargs)
  File "/usr/local/lib/python2.7/dist-packages/requests/adapters.py", line 487, in send
    raise ConnectionError(e, request=request)
requests.exceptions.ConnectionError: HTTPConnectionPool(host='teletouch.herokuapp.com', port=80): Max retries exceeded with url: /api/wake (Caused by NewConnectionError('<requests.packages.urllib3.connection.HTTPConnection object at 0x763aedf0>: Failed to establish a new connection: [Errno -2] Name or service not known',))
